#VRML_SIM R2022a utf8
# template language: javascript
  
PROTO ExcavationSquare [
  field SFString   name         "excavation_square"
  field SFVec3f    translation  0 0 0
  field SFRotation rotation     0 1 0 0
  field SFBool     flipped      FALSE
  field SFFloat    POSITION     -0.4
  field SFFloat    MIN_STOP     -0.401426
  field SFFloat    MAX_STOP     2
  field SFString{"yellow1", "yellow2", "purple1", "purple2", "red"}  frontTexture  "yellow1"
]
{
Solid {
  translation IS translation
  rotation IS rotation
  children [
    Group {
      children [
        DEF EXCAVATION_SQUARE_BOUNDING Transform {
          translation 0 -0.0075 0.035
          children [
            Shape {
              appearance DEF WALL_APPEARANCE PBRAppearance {
                baseColor 0.631 0.612 0.537
                roughness 1
                metalness 0
	            }
              geometry Box {
                size 0.185 0.015 0.07
              }
            }
          ]
        }
        Transform {
          translation -0.085 -0.0425 0.0075
          children [
            DEF EXCAVATION_SQUARE_BOTTOM_BOX Shape {
              appearance USE WALL_APPEARANCE
              geometry Box {
                size 0.015 0.055 0.015
              }
            }
          ]
        }
        Transform {
          translation 0.085 -0.0425 0.0075
          children [
            USE EXCAVATION_SQUARE_BOTTOM_BOX
          ]
        }
        Transform {
          translation -0.085 -0.02925 0.0425
          children [
            DEF EXCAVATION_SQUARE_FIRST_BOX Shape {
              appearance USE WALL_APPEARANCE
              geometry Box {
                size 0.015 0.0285 0.055
              }
            }
          ]
        }
        Transform {
          translation 0.085 -0.02925 0.0425
          children [
            USE EXCAVATION_SQUARE_FIRST_BOX
          ]
        }
        Transform {
          translation -0.085 -0.06175 0.0425
          children [
            DEF EXCAVATION_SQUARE_SECOND_BOX Shape {
              appearance USE WALL_APPEARANCE
              geometry Box {
                size 0.015 0.0165 0.055
              }
            }
          ]
        }
        Transform {
          translation 0.085 -0.06175 0.0425
          children [
            USE EXCAVATION_SQUARE_SECOND_BOX
          ]
        }
      ]
    }
    HingeJoint {
      jointParameters HingeJointParameters {
        position IS POSITION
        anchor 0 -0.0485 0.02
        minStop IS MIN_STOP
        maxStop IS MAX_STOP
      }
      endPoint Solid {
        translation 0 -0.0485 0.02
        rotation 1 0 0 %<= (fields.flipped.value) ? 3.2 : -0.4 >%
        children [
          Transform {
            translation 0 0 0.064
            children [
              Shape {
                appearance USE WALL_APPEARANCE
                geometry Box {
                  size 0.15 0.021 0.15
                }
              }
            ]
          }
          Transform {
            translation 0 0.0105 0.064
            children [
              Shape {
                appearance PBRAppearance {
                  baseColorMap ImageTexture {
                    url [ %<= '"assets/samples/excSq_' + fields.frontTexture.value + '.png"' >% ]
                    repeatS FALSE
                    repeatT FALSE
                  }
                  roughness 1
                  metalness 0
                }
                geometry Box {
                  size 0.15 0.001 0.15
                }
              }
            ]
          }
          Transform {
            translation 0 0 0.139785
            children [
              Shape {
                appearance PBRAppearance {
                  baseColor 0.768627 0.627451 0
                  baseColorMap ImageTexture {
                     url ["assets/samples/pcb.png"]
                    repeatS FALSE
                    repeatT FALSE
                  }
                  roughness 1
                  metalness 0
                }
                geometry Box {
                  size 0.1 0.02 0.00157
                }
              }
            ]
          }
        ]
        boundingObject Transform {
          translation 0 0 0.064
          children [
            Shape {
              appearance PBRAppearance {
              }
              geometry Box {
                size 0.15 0.022 0.15
              }
            }
          ]
        }
        physics Physics {
        }
      }
    }
  ]
  name IS name
  boundingObject USE EXCAVATION_SQUARE_BOUNDING
  locked TRUE
}}
