#VRML_SIM R2022a utf8
# template language: javascript

PROTO Hand [
	field SFString {"left", "right", "mid"} position "left"
	field SFString {"Dz", "G", "L"} shape "Dz"
	hiddenField SFVec3f anchor_Dz_left  -0.03030  0.1295 0.1172
    hiddenField SFVec3f anchor_Dz_right -0.03030 -0.1295 0.1172
	hiddenField SFVec3f anchor_G_left   -0.02095  0.1295 0.1397
    hiddenField SFVec3f anchor_G_right  -0.02095 -0.1295 0.1397
    hiddenField SFVec3f anchor_L_mid    -0.07655  0.0248 0.20104
	hiddenField SFVec3f x_axis 1 0 0
	hiddenField SFVec3f y_axis 0 1 0
	hiddenField SFFloat hand_mass 0.05
]
{
  %<
   var anchor;
   var axis;
   if (fields.shape.value == "Dz") {
      if (fields.position.value == "left") {
		anchor = fields.anchor_Dz_left.value;
		axis = fields.x_axis.value;
	  }
	  else {
		anchor = fields.anchor_Dz_right.value;
		axis = fields.x_axis.value;
	  }
    }
    else if (fields.shape.value == "G") {
      if (fields.position.value == "left") {
		anchor = fields.anchor_G_left.value;
		axis = fields.x_axis.value;
	  }
	  else {
		anchor = fields.anchor_G_right.value;
		axis = fields.x_axis.value;
	  }
    }
	else {
	  anchor = fields.anchor_L_mid.value;
	  axis = fields.y_axis.value;
	}
  >%
Transform {
	children [
		HingeJoint {
			jointParameters HingeJointParameters {
				axis %<= axis.x >% %<= axis.y >% %<= axis.z >%
				anchor %<= anchor.x >% %<= anchor.y >% %<= anchor.z >%
			}
			device [
				RotationalMotor {
					name %<= '"hand_' + fields.position.value + "_" + fields.shape.value + '"' >%
				}
			]
			endPoint Solid {
				name %<= '"hand_' + fields.position.value + "_" + fields.shape.value + '"' >%
				children [
					Shape {
						appearance PBRAppearance {
							baseColor 0.4 0.4 0.4
							metalness 0
							roughness 1
						}
						geometry Mesh {
							url [%<= '"assets/meshes/RobotMemristor2/hand_' + fields.shape.value +'_' + fields.position.value + '.obj"' >%]
						}
					}
					%< if (fields.shape.value == "L") { >%
						Connector {
							translation -0.09 0 0.10604
							rotation 0 0 1 3.14159
							name "hand_L_statuette_connector"
							type "active"
							numberOfRotations 0
						}
						Connector {
							translation -0.077 0 0.10604
							rotation 0 0 1 0
							name "hand_L_replica_connector"
							type "active"
							numberOfRotations 0
						}
					%< } >%
					%< if (fields.shape.value == "Dz") { >%
						TouchSensor {
							name %<= '"hand_' + fields.position.value + "_" + fields.shape.value + '_touch_sensor_front"' >%
							boundingObject Group {
								children [
									Transform {
										translation -0.0104 %<= (fields.position.value == "left") ? 0.1333 : -0.1333 >%  0.206
										rotation 1 0 0 %<= (fields.position.value == "left") ? 0.07 : -0.07 >%
										children [
											DEF resistance_pad Capsule {
												height 0.018
												radius 0.004
												subdivision 16
											}
										]
									}
								]
							}
							physics Physics {
							}
							type "force-3d"
						}
						TouchSensor {
							name %<= '"hand_' + fields.position.value + "_" + fields.shape.value + '_touch_sensor_back"' >%
							boundingObject Group {
								children [
									Transform {
										translation -0.0503 %<= (fields.position.value == "left") ? 0.1333 : -0.1333 >% 0.206
										rotation 1 0 0 %<= (fields.position.value == "left") ? 0.07 : -0.07 >%
										children [
											USE resistance_pad
										]
									}
								]
							}
							physics Physics {
							}
							type "force-3d"
						}
					%< } >%
				]
				boundingObject Transform {
					%< if (fields.shape.value == "Dz") { >%
						%< if (fields.position.value == "left") { >%
							translation %<= fields.anchor_Dz_left.value.x >% %<= fields.anchor_Dz_left.value.y >% %<= fields.anchor_Dz_left.value.z+0.046 >%
						%< } else { >%
							translation %<= fields.anchor_Dz_left.value.x >% %<= fields.anchor_Dz_right.value.y >% %<= fields.anchor_Dz_left.value.z+0.046 >%
						%< } >%
						children [
							Box {
								size 0.048 0.011 0.11
							}
						]
					%< } else if (fields.shape.value == "G") { >%
						%< if (fields.position.value == "left") { >%
							translation %<= fields.anchor_G_left.value.x-0.01 >% %<= fields.anchor_G_left.value.y >% %<= fields.anchor_G_left.value.z+0.052 >%
						%< } else { >%
							translation %<= fields.anchor_G_left.value.x-0.01 >% %<= fields.anchor_G_right.value.y >% %<= fields.anchor_G_left.value.z+0.052 >%
						%< } >%
						children [
							Box {
								size 0.072 0.02 0.126
							}
						]
					%< } else { >%
						translation %<= fields.anchor_L_mid.value.x-0.008 >% 0 %<= fields.anchor_L_mid.value.z-0.052 >%
						children [
							Box {
								size 0.013 0.073 0.09
							}
						]
					%< } >%
				}
				physics Physics {
					density -1
					mass IS hand_mass
				}
			}
		}
	]
}
}