#VRML_SIM R2021b utf8
# template language: javascript

PROTO RobotArm [
  field SFString   name         "robot_arm"
  field SFVec3f    translation  0 0 0
  field SFRotation rotation     0 1 0 0
]
{
Solid {
  translation IS translation
  rotation IS rotation
  scale 0.001 0.001 0.001
  children [
    Shape {
      appearance DEF ROBOT_ARM_APPEARANCE PBRAppearance {
        baseColor 0.631 0.612 0.537
	roughness 1
	metalness 0
      }
      geometry Mesh {
        url [
          "assets/robot_arm_mesh/arm_base.obj"
        ]
      }
    }
    HingeJoint {
      jointParameters HingeJointParameters {
        axis 0 0 1
      }
      device [
	RotationalMotor {
	  name "motor_arm_1"
	  maxTorque 100
	}
      ]
      endPoint Solid {
        translation 0 82 0
        rotation 0 0 1 0
        children [
          DEF ARM_MID_SHAPE Shape {
            appearance USE ROBOT_ARM_APPEARANCE 
            geometry Mesh {
              url [
                "assets/robot_arm_mesh/arm_mid.obj"
              ]
            }
          }
          HingeJoint {
            jointParameters HingeJointParameters {
              axis 0 0 1
            }
            device [
              RotationalMotor {
                name "motor_arm_2"
                maxTorque 100
              }
            ]
            endPoint Solid {
              translation 0 82 0
              rotation 0 0 1 0
              children [
                USE ARM_MID_SHAPE
                HingeJoint {
                  jointParameters HingeJointParameters {
                    axis 0 0 1
                  }
                  device [
                    RotationalMotor {
                      name "motor_arm_3"
                      maxTorque 100
                    }
                  ]
                  endPoint Solid {
                    rotation 0 0 1 0
                    children [
                      Shape {
                        appearance USE ROBOT_ARM_APPEARANCE
                        geometry Mesh {
                          url [
                            "assets/robot_arm_mesh/arm_vaccuum.obj"
                          ]
                        }
                      }
                    ]
                    boundingObject Transform {
                      translation 0 28 0
                      children [
                        Box {
                          size 28 80 48
                        }
                      ]
                    }
                    physics Physics {
                    }
                  }
                }
              ]
              boundingObject DEF TEST Transform {
                translation 0 -40 0
                children [
                  Box {
                    size 34 114 50
                  }
                ]
              }
              physics Physics {
              }
            }
          }
        ]
        boundingObject DEF TEST2 Transform {
          translation 0 -40 0
          children [
            Box {
              size 34 114 50
            }
          ]
        }
        physics Physics {
        }
      }
    }
  ]
  name IS name
  boundingObject Transform {
    translation 0 -10.5 0
    children [
      Box {
        size 36 57 50
      }
    ]
  }
  physics Physics {
  }
}
}
