#VRML_SIM R2021b utf8
# template language: javascript

PROTO RobotArm [
  field SFString   name         "robot_arm"
  field SFVec3f    translation  0 0 0
  field SFRotation rotation     0 1 0 0
]
{
Solid {
  translation IS translation
  rotation IS rotation
  scale 1 1 1
  children [
    Shape {
      appearance DEF ROBOT_ARM_APPEARANCE PBRAppearance {
        baseColor 0.631 0.612 0.537
	roughness 1
	metalness 0
      }
      geometry Mesh {
        url [
          "assets/robot_arm_mesh/arm_base.obj"
        ]
      }
    }
    HingeJoint {
      jointParameters HingeJointParameters {
        axis 0 0 1
      }
      device [
	RotationalMotor {
	  name "motor_arm_0"
	  maxTorque 100
	}
	PositionSensor {
          name "sensor_arm_0"
        }
      ]
      endPoint Solid {
        translation 0 0.082 0
        rotation 0 0 1 0
        children [
          DEF ARM_MID_SHAPE Shape {
            appearance USE ROBOT_ARM_APPEARANCE 
            geometry Mesh {
              url [
                "assets/robot_arm_mesh/arm_mid.obj"
              ]
            }
          }
          HingeJoint {
            jointParameters HingeJointParameters {
              axis 0 0 1
            }
            device [
              RotationalMotor {
                name "motor_arm_1"
                maxTorque 100
              }
              PositionSensor {
                name "sensor_arm_1"
              }
            ]
            endPoint Solid {
              translation 0 0.082 0
              rotation 0 0 1 0
              children [
                USE ARM_MID_SHAPE
                HingeJoint {
                  jointParameters HingeJointParameters {
                    axis 0 0 1
                  }
                  device [
                    RotationalMotor {
                      name "motor_arm_2"
                      maxTorque 100
                    }
                    PositionSensor {
                      name "sensor_arm_2"
                    }
                  ]
                  endPoint Solid {
                    rotation 0 0 1 0
                    children [
                      Shape {
                        appearance USE ROBOT_ARM_APPEARANCE
                        geometry Mesh {
                          url [
                            "assets/robot_arm_mesh/arm_vaccuum.obj"
                          ]
                        }
                      }
                      Connector {
                        translation 0 0.068 0
                        rotation 1 0 0 -1.5707996938995747
                        type "active"
                        numberOfRotations 0
                      }
                    ]
                    boundingObject Transform {
                      translation 0 0.028 0
                      children [
                        Box {
                          size 0.028 0.080 0.048
                        }
                      ]
                    }
                    physics Physics {
                      density -1
                      mass 0.1
                    }
                  }
                }
              ]
              boundingObject DEF ROBOT_ARM_MID_BOUNDING_BOX Transform {
                translation 0 -0.040 0
                children [
                  Box {
                    size 0.034 0.114 0.050
                  }
                ]
              }
              physics Physics {
                density -1
                mass 0.2
              }
            }
          }
        ]
        boundingObject USE ROBOT_ARM_MID_BOUNDING_BOX 
        physics Physics {
          density -1
          mass 0.2
        }
      }
    }
  ]
  name IS name
  boundingObject Transform {
    translation 0 -0.0105 0
    children [
      Box {
        size 0.036 0.057 0.050
      }
    ]
  }
  physics Physics {
    density -1
    mass 0.15
  }
}
}
