#VRML_SIM R2021b utf8
WorldInfo {
  CFM 1e-08
  basicTimeStep 16
}
Viewpoint {
  orientation -0.6185156533799401 0.42568054164409 0.6604804788860755 4.6712462194513
  position -0.9416889971908979 -0.3746245908161882 0.6552406012728842
}
TexturedBackground {
}
TexturedBackgroundLight {
}
Floor {
  rotation 1 0 0 1.5707996938995747
  name "table"
  size 3 2
  tileSize 4.096 2.048
  appearance PBRAppearance {
    baseColorMap ImageTexture {
      url [
        "assets/table_pow2.png"
      ]
      repeatS FALSE
      repeatT FALSE
    }
    roughness 1
    metalness 0
  }
}
Solid {
  translation 0.035 -1.009 0
  rotation 1 0 0 1.5708
  children [
    DEF WALL_W Shape {
      appearance DEF WALL_APPEARANCE PBRAppearance {
        baseColor 1 1 0.498039
        roughness 1
        metalness 0
      }
      geometry Box {
        size 3 0.07 0.018
      }
    }
  ]
  name "wall_top"
  boundingObject USE WALL_W
}
Solid {
  translation -0.005 1.019 3.67321e-08
  rotation 1 0 0 1.5708
  children [
    USE WALL_W
  ]
  name "wall_bottom"
  boundingObject USE WALL_W
}
Solid {
  translation -1.509 0.035 0
  rotation 1 0 0 1.5708
  children [
    DEF WALL_H Shape {
      appearance USE WALL_APPEARANCE
      geometry Box {
        size 0.018 0.07 2.036
      }
    }
  ]
  name "wall_left"
  boundingObject USE WALL_H
}
Solid {
  translation 1.509 0.035 0
  rotation 1 0 0 1.5708
  children [
    USE WALL_H
  ]
  name "wall_right"
  boundingObject USE WALL_H
}
Robot {
  translation 0 0 0.2
  children [
    DEF ROBOT_BODY Shape {
      appearance DEF ROBOT_METAL PBRAppearance {
        baseColor 1 0.333333 1
        roughness 0.6
        metalness 0.3
      }
      geometry Box {
        size 0.2 0.36 0.33
      }
    }
    HingeJoint {
      jointParameters HingeJointParameters {
        axis 0 1 0
        anchor 0 -0.185 -0.13
      }
      device [
        RotationalMotor {
        }
      ]
      endPoint Solid {
        translation 0 -0.185 -0.13
        children [
          DEF ROBOT_WHEEL Shape {
            appearance PBRAppearance {
              baseColor 0.666667 1 0
              roughness 1
              metalness 0
            }
            geometry Cylinder {
              height 0.02
              radius 0.05
            }
          }
        ]
        name "wheel_r"
        boundingObject USE ROBOT_WHEEL
        physics Physics {
        }
      }
    }
  ]
  boundingObject USE ROBOT_BODY
  physics Physics {
    density -1
    mass 10
  }
}
