#VRML_SIM R2021b utf8
WorldInfo {
}
Viewpoint {
  orientation -0.9752204345718972 -0.21609011713267887 0.04743590697968239 0.6431899531396247
  position -0.7599591916138844 3.2259880963770233 3.8203397491537685
}
TexturedBackground {
}
TexturedBackgroundLight {
}
Floor {
  name "table"
  size 3 2
  tileSize 4.096 2.048
  appearance PBRAppearance {
    baseColorMap ImageTexture {
      url [
        "assets/table_pow2.png"
      ]
      repeatS FALSE
      repeatT FALSE
    }
    roughness 1
    metalness 0
  }
}
Solid {
  translation 0 0.035 -1.009
  children [
    DEF WALL_W Shape {
      appearance DEF WALL_APPEARANCE PBRAppearance {
        baseColor 1 1 0.498039
        roughness 1
        metalness 0
      }
      geometry Box {
        size 3 0.07 0.018
      }
    }
  ]
  name "wall_top"
  boundingObject USE WALL_W
}
Solid {
  translation 0 0.035 1.009
  children [
    USE WALL_W
  ]
  name "wall_bottom"
  boundingObject USE WALL_W
}
Solid {
  translation -1.509 0.035 0
  children [
    DEF WALL_H Shape {
      appearance USE WALL_APPEARANCE
      geometry Box {
        size 0.018 0.07 2.036
      }
    }
  ]
  name "wall_left"
  boundingObject USE WALL_H
}
Solid {
  translation 1.509 0.035 0
  children [
    USE WALL_H
  ]
  name "wall_right"
  boundingObject USE WALL_H
}
Robot {
  translation 0 0.25 0
  children [
    DEF ROBOT_BODY Shape {
      appearance DEF ROBOT_METAL PBRAppearance {
        baseColor 1 0.333333 1
        roughness 0.6
        metalness 0.3
      }
      geometry Box {
        size 0.2 0.33 0.36
      }
    }
    HingeJoint {
      jointParameters HingeJointParameters {
      }
      endPoint Solid {
        translation 0 -0.155 0.19
        rotation 1 0 0 1.5708
        children [
          DEF ROBOT_WHEEL Shape {
            appearance PBRAppearance {
              baseColor 0.666667 1 0
              roughness 1
              metalness 0
            }
            geometry Cylinder {
              height 0.02
              radius 0.05
            }
          }
        ]
        name "wheel_r"
        boundingObject USE ROBOT_WHEEL
      }
    }
  ]
  physics Physics {
  }
}
