#VRML_SIM R2021b utf8
WorldInfo {
  CFM 1e-08
  basicTimeStep 16
}
Viewpoint {
  orientation 0.20868380639246203 -0.4933479470449755 -0.8444281331741982 2.455462865957651
  position -0.970213014458458 1.0796919983826436 1.0058115311780271
}
TexturedBackground {
}
TexturedBackgroundLight {
}
Floor {
  rotation 1 0 0 1.5707996938995747
  name "table"
  size 3 2
  tileSize 4.096 2.048
  appearance PBRAppearance {
    baseColorMap ImageTexture {
      url [
        "assets/table.png"
      ]
      repeatS FALSE
      repeatT FALSE
    }
    roughness 1
    metalness 0
  }
}
Solid {
  children [
    DEF purple_statuette_support_shape Group {
      children [
        Shape {
          appearance DEF APPEARANCE_PURPLE PBRAppearance {
            baseColor 0.360784 0.282353 0.541176
            roughness 1
            metalness 0
            name "purple"
          }
          geometry IndexedFaceSet {
            coord Coordinate {
              point [
                1.5 -0.49 0.07
                1.5 -0.49 0.048
                1.5 -0.69082 0.07
                1.5 -0.69082 0.048
                0.99 -1 0.07
                0.99 -1 0.048
                1.19082 -1 0.07
                1.19082 -1 0.048
              ]
            }
            normal Normal {
              vector [
                0 0 1
                0 0 1
                0 0 -1
                0 0 -1
                1 0 0
                1 0 0
                -0.70711 0.70711 0
                -0.70711 0.70711 0
                0 -1 0
                0 -1 0
                0.70711 -0.70711 0
                0.70711 -0.70711 0
              ]
            }
            normalPerVertex FALSE
            coordIndex [
              0, 4, 2, -1, 2, 4, 6, -1, 1, 3, 5, -1, 3, 7, 5, -1, 0, 2, 1, -1, 1, 2, 3, -1, 0, 1, 4, -1, 1, 5, 4, -1, 4, 5, 6, -1, 5, 7, 6, -1, 2, 6, 3, -1, 3, 6, 7, -1
            ]
          }
          isPickable FALSE
        }
        Transform {
          translation 1.28743 -0.78743 0.081
          rotation 0 0 1 0.7853996938995746
          children [
            Shape {
              appearance USE APPEARANCE_PURPLE
              geometry Box {
                size 0.12 0.12 0.022
              }
            }
          ]
        }
        Transform {
          translation 1.33763 -0.83763 0.081
          rotation 0 0 1 0.7853996938995746
          children [
            Shape {
              appearance USE APPEARANCE_PURPLE
              geometry Box {
                size 0.481249 0.022 0.022
              }
            }
          ]
        }
      ]
    }
  ]
  name "purple statuette support"
  boundingObject USE purple_statuette_support_shape
  locked TRUE
}
Solid {
  children [
    DEF yellow_statuette_support_shape Group {
      children [
        Shape {
          appearance DEF APPEARANCE_YELLOW PBRAppearance {
            baseColor 0.972549 0.694118 0.0666667
            roughness 1
            metalness 0
            name "yellow"
          }
          geometry IndexedFaceSet {
            coord Coordinate {
              point [
                -1.5 -0.49 0.07
                -1.5 -0.49 0.048
                -1.5 -0.69082 0.07
                -1.5 -0.69082 0.048
                -0.99 -1 0.07
                -0.99 -1 0.048
                -1.19082 -1 0.07
                -1.19082 -1 0.048
              ]
            }
            normal Normal {
              vector [
                0 0 1
                0 0 1
                0 0 -1
                0 0 -1
                1 0 0
                1 0 0
                -0.70711 0.70711 0
                -0.70711 0.70711 0
                0 -1 0
                0 -1 0
                0.70711 -0.70711 0
                0.70711 -0.70711 0
              ]
            }
            normalPerVertex FALSE
            coordIndex [
              0, 2, 4, -1, 2, 6, 4, -1, 1, 5, 3, -1, 3, 5, 7, -1, 0, 1, 2, -1, 1, 3, 2, -1, 0, 4, 1, -1, 1, 4, 5, -1, 4, 6, 5, -1, 5, 6, 7, -1, 2, 3, 6, -1, 3, 7, 6, -1
            ]
          }
          isPickable FALSE
        }
        Transform {
          translation -1.28743 -0.78743 0.081
          rotation 0 0 1 0.7853996938995746
          children [
            Shape {
              appearance USE APPEARANCE_YELLOW
              geometry Box {
                size 0.12 0.12 0.022
              }
            }
          ]
        }
        Transform {
          translation -1.33763 -0.83763 0.081
          rotation 0 0 1 -0.7854
          children [
            Shape {
              appearance USE APPEARANCE_YELLOW
              geometry Box {
                size 0.481249 0.022 0.022
              }
            }
          ]
        }
      ]
    }
  ]
  name "yellow statuette support"
  boundingObject USE yellow_statuette_support_shape
  locked TRUE
}
Solid {
  translation 0 1.011 0.035
  rotation 1 0 0 1.5708
  children [
    DEF WALL_W Shape {
      appearance DEF WALL_APPEARANCE PBRAppearance {
        baseColor 1 1 0.498039
        roughness 1
        metalness 0
      }
      geometry Box {
        size 3 0.07 0.022
      }
      isPickable FALSE
    }
  ]
  name "wall_top"
  boundingObject USE WALL_W
  locked TRUE
}
Solid {
  translation 0 -1.011 0.035
  rotation 1 0 0 1.5708
  children [
    USE WALL_W
  ]
  name "wall_bottom"
  boundingObject USE WALL_W
  locked TRUE
}
Solid {
  translation -1.511 0 0.035
  rotation 1 0 0 1.5708
  children [
    DEF WALL_H Shape {
      appearance USE WALL_APPEARANCE
      geometry Box {
        size 0.022 0.07 2.044
      }
      isPickable FALSE
    }
  ]
  name "wall_left"
  boundingObject USE WALL_H
  locked TRUE
}
Solid {
  translation 1.511 0 0.035
  rotation 1 0 0 1.5708
  children [
    USE WALL_H
  ]
  name "wall_right"
  boundingObject USE WALL_H
  locked TRUE
}
Sample {
  name "sample_purple_excavation_site_red"
  translation 0.442219 -0.454349 0.0075
  rotation 0 0 1 -0.785395307179586
  frontTexture "red"
}
Sample {
  name "sample_purple_excavation_site_green"
  translation 0.531922 -0.303676 0.0075
  rotation 0 0 1 1.309
  frontTexture "green"
}
Sample {
  name "sample_purple_excavation_site_blue"
  translation 0.61144 -0.45196 0.0075
  rotation 0 0 1 -2.6179953071795863
  frontTexture "blue"
}
Sample {
  name "sample_yellow_excavation_site_red"
  translation -0.446015 -0.290911 0.0075
  rotation 0 0 1 -0.261795307179586
  frontTexture "red"
}
Sample {
  name "sample_yellow_excavation_site_green"
  translation -0.608832 -0.343505 0.0075
  rotation 0 0 1 -1.3089953071795861
  frontTexture "green"
}
Sample {
  name "sample_yellow_excavation_site_blue"
  translation -0.498243 -0.466137 0.0075
  rotation 0 0 1 -2.094395307179586
  frontTexture "blue"
}
Sample {
  name "sample_purple_playing_area_red"
  translation 0.6 0.2 0.00750369
  rotation 0.7071067811862364 0.7071067811862364 9.381857096790023e-07 3.14159
  frontTexture "red"
}
Sample {
  name "sample_purple_playing_area_green"
  translation 0.67 0.325 0.00750385
  rotation 0.7071067811862364 0.7071067811862364 9.381857096790023e-07 3.14159
  frontTexture "green"
}
Sample {
  name "sample_purple_playing_area_blue"
  translation 0.6 0.45 0.00750346
  rotation 0.7071067811862364 0.7071067811862364 9.381857096790023e-07 3.14159
  frontTexture "blue"
}
Sample {
  name "sample_yellow_playing_area_red"
  translation -0.6 0.2 0.00749988
  rotation 0.7071067811862364 0.7071067811862364 9.381857096790023e-07 3.14159
  frontTexture "red"
}
Sample {
  name "sample_yellow_playing_area_green"
  translation -0.67 0.325 0.00749957
  rotation 0.7071067811862364 0.7071067811862364 9.381857096790023e-07 3.14159
  frontTexture "green"
}
Sample {
  name "sample_yellow_playing_area_blue"
  translation -0.6 0.45 0.00749969
  rotation 0.7071067811862364 0.7071067811862364 9.381857096790023e-07 3.14159
  frontTexture "blue"
}
Solid {
  translation 0 1.233 0
  children [
    Transform {
      translation 0 0 0.5
      children [
        Shape {
          appearance USE WALL_APPEARANCE
          geometry Box {
            size 0.2 0.022 1
          }
        }
        Transform {
          translation 0 -0.11 -0.011
          children [
            Shape {
              appearance USE WALL_APPEARANCE
              geometry Box {
                size 0.022 0.2 0.978
              }
            }
          ]
        }
        Group {
          children [
            Transform {
              translation -0.1 -0.0585 0.489
              children [
                Shape {
                  appearance USE APPEARANCE_YELLOW
                  geometry DEF CENTRAL_TRACKING_TOP_BOX_HALF Box {
                    size 0.2 0.095 0.022
                  }
                }
              ]
            }
            Transform {
              translation -0.0475 -0.111 0.489
              children [
                Shape {
                  appearance USE APPEARANCE_YELLOW
                  geometry DEF CENTRAL_TRACKING_BOX_SLIT Box {
                    size 0.095 0.01 0.022
                  }
                }
              ]
            }
            Transform {
              translation -0.1 -0.1635 0.489
              children [
                Shape {
                  appearance USE APPEARANCE_YELLOW
                  geometry USE CENTRAL_TRACKING_TOP_BOX_HALF
                }
              ]
            }
          ]
        }
        Group {
          children [
            Transform {
              translation 0.1 -0.0585 0.489
              children [
                Shape {
                  appearance USE APPEARANCE_PURPLE
                  geometry USE CENTRAL_TRACKING_TOP_BOX_HALF
                }
              ]
            }
            Transform {
              translation 0.0475 -0.111 0.489
              children [
                Shape {
                  appearance USE APPEARANCE_PURPLE
                  geometry USE CENTRAL_TRACKING_BOX_SLIT
                }
              ]
            }
            Transform {
              translation 0.1 -0.1635 0.489
              children [
                Shape {
                  appearance USE APPEARANCE_PURPLE
                  geometry USE CENTRAL_TRACKING_TOP_BOX_HALF
                }
              ]
            }
          ]
        }
      ]
    }
  ]
  name "central_tracking_device_platform"
  boundingObject Transform {
    translation 0 -0.111 0.989
    children [
      Box {
        size 0.4 0.2 0.022
      }
    ]
  }
  locked TRUE
}
Robot {
  children [
    DEF ROBOT_BODY_BOUND Transform {
      translation 0 0 0.175
      children [
        DEF ROBOT_BODY Shape {
          appearance CorrodedMetal {
            IBLStrength 20
          }
          geometry Box {
            size 0.2 0.36 0.34
          }
        }
      ]
    }
    HingeJoint {
      jointParameters HingeJointParameters {
        axis 0 1 0
        anchor 0 -0.19 0.05
      }
      device [
        RotationalMotor {
          name "motor_r"
        }
      ]
      endPoint Solid {
        translation 0 -0.19 0.05
        children [
          DEF ROBOT_WHEEL Shape {
            appearance Rubber {
            }
            geometry Cylinder {
              height 0.02
              radius 0.05
            }
          }
        ]
        name "wheel_r"
        boundingObject USE ROBOT_WHEEL
        physics Physics {
        }
      }
    }
    HingeJoint {
      jointParameters HingeJointParameters {
        axis 0 1 0
        anchor 0 0.19 0.05
      }
      device [
        RotationalMotor {
          name "motor_l"
        }
      ]
      endPoint Solid {
        translation 0 0.19 0.05
        rotation 0 -1 0 0.08462082290631825
        children [
          USE ROBOT_WHEEL
        ]
        name "wheel_l"
        boundingObject USE ROBOT_WHEEL
        physics Physics {
        }
      }
    }
  ]
  boundingObject USE ROBOT_BODY_BOUND
  physics Physics {
    density -1
    mass 10
  }
}
