#VRML_SIM R2021b utf8
WorldInfo {
  CFM 1e-08
  basicTimeStep 16
}
Viewpoint {
  orientation 0.6476612670397272 0.36068233024986585 0.6711506088964102 1.3852615184625288
  position 2.727497687901888 -1.040335242029225 1.4596110532408784
}
TexturedBackground {
}
TexturedBackgroundLight {
}
Floor {
  rotation 1 0 0 1.5707996938995747
  name "table"
  size 3 2
  tileSize 4.096 2.048
  appearance PBRAppearance {
    baseColorMap ImageTexture {
      url [
        "assets/table.png"
      ]
      repeatS FALSE
      repeatT FALSE
    }
    roughness 1
    metalness 0
  }
}
Solid {
  translation 0 1.009 0.035
  rotation 1 0 0 1.5708
  children [
    DEF WALL_W Shape {
      appearance DEF WALL_APPEARANCE PBRAppearance {
        baseColor 1 1 0.498039
        roughness 1
        metalness 0
      }
      geometry Box {
        size 3 0.07 0.018
      }
    }
  ]
  name "wall_top"
  boundingObject USE WALL_W
}
Solid {
  translation 0 -1.009 0.035
  rotation 1 0 0 1.5708
  children [
    USE WALL_W
  ]
  name "wall_bottom"
  boundingObject USE WALL_W
}
Solid {
  translation -1.509 0 0.035
  rotation 1 0 0 1.5708
  children [
    DEF WALL_H Shape {
      appearance USE WALL_APPEARANCE
      geometry Box {
        size 0.018 0.07 2.036
      }
    }
  ]
  name "wall_left"
  boundingObject USE WALL_H
}
Solid {
  translation 1.509 0 0.035
  rotation 1 0 0 1.5708
  children [
    USE WALL_H
  ]
  name "wall_right"
  boundingObject USE WALL_H
}
Sample {
  name "sample_purple_excavation_site_red"
  translation 0.442219 -0.454349 0.0075
  rotation 0 0 1 -0.785395307179586
  frontTexture "red"
}
Sample {
  name "sample_purple_excavation_site_green"
  translation 0.531922 -0.303676 0.0075
  rotation 0 0 1 1.309
  frontTexture "green"
}
Sample {
  name "sample_purple_excavation_site_blue"
  translation 0.61144 -0.45196 0.0075
  rotation 0 0 1 -2.6179953071795863
  frontTexture "blue"
}
Sample {
  name "sample_yellow_excavation_site_red"
  translation -0.446015 -0.290911 0.0075
  rotation 0 0 1 -0.261795307179586
  frontTexture "red"
}
Sample {
  name "sample_yellow_excavation_site_green"
  translation -0.608832 -0.343505 0.0075
  rotation 0 0 1 -1.3089953071795861
  frontTexture "green"
}
Sample {
  name "sample_yellow_excavation_site_blue"
  translation -0.498243 -0.466137 0.0075
  rotation 0 0 1 -2.094395307179586
  frontTexture "blue"
}
Sample {
  name "sample_purple_playing_area_red"
  translation 0.6 0.2 0.00750369
  rotation 0.7071067811862364 0.7071067811862364 9.381857096790023e-07 3.14159
  frontTexture "red"
}
Sample {
  name "sample_purple_playing_area_green"
  translation 0.67 0.325 0.00750385
  rotation 0.7071067811862364 0.7071067811862364 9.381857096790023e-07 3.14159
  frontTexture "green"
}
Sample {
  name "sample_purple_playing_area_blue"
  translation 0.6 0.45 0.00750346
  rotation 0.7071067811862364 0.7071067811862364 9.381857096790023e-07 3.14159
  frontTexture "blue"
}
Sample {
  name "sample_yellow_playing_area_red"
  translation -0.6 0.2 0.00749988
  rotation 0.7071067811862364 0.7071067811862364 9.381857096790023e-07 3.14159
  frontTexture "red"
}
Sample {
  name "sample_yellow_playing_area_green"
  translation -0.67 0.325 0.00749957
  rotation 0.7071067811862364 0.7071067811862364 9.381857096790023e-07 3.14159
  frontTexture "green"
}
Sample {
  name "sample_yellow_playing_area_blue"
  translation -0.6 0.45 0.00749969
  rotation 0.7071067811862364 0.7071067811862364 9.381857096790023e-07 3.14159
  frontTexture "blue"
}
Robot {
  translation 0.27 0 0
  children [
    DEF ROBOT_BODY_BOUND Transform {
      translation 0 0 0.175
      children [
        DEF ROBOT_BODY Shape {
          appearance CorrodedMetal {
            IBLStrength 20
          }
          geometry Box {
            size 0.2 0.36 0.34
          }
        }
      ]
    }
    HingeJoint {
      jointParameters HingeJointParameters {
        axis 0 1 0
        anchor 0 -0.19 0.05
      }
      device [
        RotationalMotor {
          name "motor_r"
        }
      ]
      endPoint Solid {
        translation 0 -0.19 0.05
        children [
          DEF ROBOT_WHEEL Shape {
            appearance Rubber {
            }
            geometry Cylinder {
              height 0.02
              radius 0.05
            }
          }
        ]
        name "wheel_r"
        boundingObject USE ROBOT_WHEEL
        physics Physics {
        }
      }
    }
    HingeJoint {
      jointParameters HingeJointParameters {
        axis 0 1 0
        anchor 0 0.19 0.05
      }
      device [
        RotationalMotor {
          name "motor_l"
        }
      ]
      endPoint Solid {
        translation 0 0.19 0.05
        rotation 0 -1 0 0.08462082290631825
        children [
          USE ROBOT_WHEEL
        ]
        name "wheel_l"
        boundingObject USE ROBOT_WHEEL
        physics Physics {
        }
      }
    }
  ]
  boundingObject USE ROBOT_BODY_BOUND
  physics Physics {
    density -1
    mass 10
  }
}
Solid {
  children [
    Transform {
      translation -0.15 1 0
      children [
        DEF dispenser Group {
          children [
            Transform {
              translation 0 -0.011 0.011
              children [
                Shape {
                  appearance USE WALL_APPEARANCE
                  geometry Box {
                    size 0.106 0.022 0.022
                  }
                  isPickable FALSE
                }
              ]
            }
            Transform {
              translation 0.064 -0.04 0.011
              children [
                Shape {
                  appearance USE WALL_APPEARANCE
                  geometry Box {
                    size 0.022 0.08 0.022
                  }
                  isPickable FALSE
                }
              ]
            }
            Transform {
              translation -0.064 -0.04 0.011
              children [
                Shape {
                  appearance USE WALL_APPEARANCE
                  geometry Box {
                    size 0.022 0.08 0.022
                  }
                  isPickable FALSE
                }
              ]
            }
            Transform {
              translation 0 -0.091 0.011
              children [
                Shape {
                  appearance USE WALL_APPEARANCE
                  geometry Box {
                    size 0.15 0.022 0.022
                  }
                  isPickable FALSE
                }
              ]
            }
          ]
        }
      ]
    }
  ]
  name "dispenser_left"
  boundingObject Transform {
    translation -0.15 1 0
  }
  locked TRUE
}
Solid {
  children [
    Transform {
      translation 0.15 1 0
      children [
        DEF dispenser Group {
          children [
            Transform {
              translation 0 -0.011 0.011
              children [
                Shape {
                  appearance USE WALL_APPEARANCE
                  geometry Box {
                    size 0.106 0.022 0.022
                  }
                  isPickable FALSE
                }
              ]
            }
            Transform {
              translation 0.064 -0.04 0.011
              children [
                Shape {
                  appearance USE WALL_APPEARANCE
                  geometry Box {
                    size 0.022 0.08 0.022
                  }
                  isPickable FALSE
                }
              ]
            }
            Transform {
              translation -0.064 -0.04 0.011
              children [
                Shape {
                  appearance USE WALL_APPEARANCE
                  geometry Box {
                    size 0.022 0.08 0.022
                  }
                  isPickable FALSE
                }
              ]
            }
            Transform {
              translation 0 -0.091 0.011
              children [
                Shape {
                  appearance USE WALL_APPEARANCE
                  geometry Box {
                    size 0.15 0.022 0.022
                  }
                  isPickable FALSE
                }
              ]
            }
          ]
        }
      ]
    }
  ]
  name "dispenser_right"
  boundingObject Transform {
    translation 0.15 1 0
  }
  locked TRUE
}
Solid {
  children [
    Transform {
      translation -1.5 -0.25 0
      rotation 0 0 1 1.5708003061004252
      children [
        DEF dispenser Group {
          children [
            Transform {
              translation 0 -0.011 0.011
              children [
                Shape {
                  appearance USE WALL_APPEARANCE
                  geometry Box {
                    size 0.106 0.022 0.022
                  }
                  isPickable FALSE
                }
              ]
            }
            Transform {
              translation 0.064 -0.04 0.011
              children [
                Shape {
                  appearance USE WALL_APPEARANCE
                  geometry Box {
                    size 0.022 0.08 0.022
                  }
                  isPickable FALSE
                }
              ]
            }
            Transform {
              translation -0.064 -0.04 0.011
              children [
                Shape {
                  appearance USE WALL_APPEARANCE
                  geometry Box {
                    size 0.022 0.08 0.022
                  }
                  isPickable FALSE
                }
              ]
            }
            Transform {
              translation 0 -0.091 0.011
              children [
                Shape {
                  appearance USE WALL_APPEARANCE
                  geometry Box {
                    size 0.15 0.022 0.022
                  }
                  isPickable FALSE
                }
              ]
            }
          ]
        }
      ]
    }
  ]
  name "dispenser_yellow"
  boundingObject Transform {
    translation -1.5 -0.25 0
    rotation 0 0 1 1.5708003061004252
  }
  locked TRUE
}
Solid {
  children [
    Transform {
      translation 1.5 -0.25 0
      rotation 0 0 1 -1.5708
      children [
        DEF dispenser Group {
          children [
            Transform {
              translation 0 -0.011 0.011
              children [
                Shape {
                  appearance USE WALL_APPEARANCE
                  geometry Box {
                    size 0.106 0.022 0.022
                  }
                  isPickable FALSE
                }
              ]
            }
            Transform {
              translation 0.064 -0.04 0.011
              children [
                Shape {
                  appearance USE WALL_APPEARANCE
                  geometry Box {
                    size 0.022 0.08 0.022
                  }
                  isPickable FALSE
                }
              ]
            }
            Transform {
              translation -0.064 -0.04 0.011
              children [
                Shape {
                  appearance USE WALL_APPEARANCE
                  geometry Box {
                    size 0.022 0.08 0.022
                  }
                  isPickable FALSE
                }
              ]
            }
            Transform {
              translation 0 -0.091 0.011
              children [
                Shape {
                  appearance USE WALL_APPEARANCE
                  geometry Box {
                    size 0.15 0.022 0.022
                  }
                  isPickable FALSE
                }
              ]
            }
          ]
        }
      ]
    }
  ]
  name "dispenser_purple"
  boundingObject Transform {
    translation 1.5 -0.25 0
    rotation 0 0 1 -1.5708
  }
  locked TRUE
}
Solid {
  translation -1.522 0.7 0
  children [
    DEF dispenser_outer Shape {
      appearance USE WALL_APPEARANCE
      geometry IndexedFaceSet {
        coord Coordinate {
          point [
            0 0.075 0.07
            -0.04295 0.075 0.07
            -0.107902 0.0375 0.07
            -0.107902 -0.0375 0.07
            -0.04295 -0.075 0.07
            0 -0.075 0.07
          ]
        }
        normal Normal {
          vector [
            0 0 1
            0 0 1
            0 0 1
            0 0 1
          ]
        }
        normalPerVertex FALSE
        coordIndex [
          0, 1, 2, -1, 0, 2, 3, -1, 0, 3
          4, -1, 0, 4, 5, -1
        ]
      }
      isPickable FALSE
    }
  ]
  name "dispenser_yellow_outer"
  boundingObject Shape {
    appearance USE WALL_APPEARANCE
    geometry IndexedFaceSet {
      coord Coordinate {
        point [
          0 0.075 0.07
          -0.04295 0.075 0.07
          -0.107902 0.0375 0.07
          -0.107902 -0.0375 0.07
          -0.04295 -0.075 0.07
          0 -0.075 0.07
        ]
      }
      normal Normal {
        vector [
          0 0 1
          0 0 1
          0 0 1
          0 0 1
        ]
      }
      normalPerVertex FALSE
      coordIndex [
        0, 1, 2, -1, 0, 2, 3, -1, 0, 3
        4, -1, 0, 4, 5, -1
      ]
    }
    isPickable FALSE
  }
}
Solid {
  translation 1.522 0.7 0
  rotation 0 0 1 3.141592653589793
  children [
    DEF dispenser_outer Shape {
      appearance USE WALL_APPEARANCE
      geometry IndexedFaceSet {
        coord Coordinate {
          point [
            0 0.075 0.07
            -0.04295 0.075 0.07
            -0.107902 0.0375 0.07
            -0.107902 -0.0375 0.07
            -0.04295 -0.075 0.07
            0 -0.075 0.07
          ]
        }
        normal Normal {
          vector [
            0 0 1
            0 0 1
            0 0 1
            0 0 1
          ]
        }
        normalPerVertex FALSE
        coordIndex [
          0, 1, 2, -1, 0, 2, 3, -1, 0, 3
          4, -1, 0, 4, 5, -1
        ]
      }
      isPickable FALSE
    }
  ]
  name "dispenser_purple_outer"
  boundingObject Shape {
    appearance USE WALL_APPEARANCE
    geometry IndexedFaceSet {
      coord Coordinate {
        point [
          0 0.075 0.07
          -0.04295 0.075 0.07
          -0.107902 0.0375 0.07
          -0.107902 -0.0375 0.07
          -0.04295 -0.075 0.07
          0 -0.075 0.07
        ]
      }
      normal Normal {
        vector [
          0 0 1
          0 0 1
          0 0 1
          0 0 1
        ]
      }
      normalPerVertex FALSE
      coordIndex [
        0, 1, 2, -1, 0, 2, 3, -1, 0, 3
        4, -1, 0, 4, 5, -1
      ]
    }
    isPickable FALSE
  }
}
