#VRML_SIM R2021b utf8
WorldInfo {
  CFM 1e-08
  basicTimeStep 16
}
Viewpoint {
  orientation 0.20868380639246203 -0.4933479470449755 -0.8444281331741982 2.455462865957651
  position -0.970213014458458 1.0796919983826436 1.0058115311780271
}
TexturedBackground {
}
TexturedBackgroundLight {
}
Floor {
  rotation 1 0 0 1.5707996938995747
  name "table"
  size 3 2
  tileSize 4.096 2.048
  appearance PBRAppearance {
    baseColorMap ImageTexture {
      url [
        "assets/table_pow2.png"
      ]
      repeatS FALSE
      repeatT FALSE
    }
    roughness 1
    metalness 0
  }
}
Solid {
  translation 0 1.011 0.035
  rotation 1 0 0 1.5708
  children [
    DEF WALL_W Shape {
      appearance DEF WALL_APPEARANCE PBRAppearance {
        baseColor 1 1 0.498039
        roughness 1
        metalness 0
      }
      geometry Box {
        size 3 0.07 0.022
      }
    }
  ]
  name "wall_top"
  boundingObject USE WALL_W
}
Solid {
  translation 0 -1.011 0.035
  rotation 1 0 0 1.5708
  children [
    USE WALL_W
  ]
  name "wall_bottom"
  boundingObject USE WALL_W
}
Solid {
  translation -1.511 0 0.035
  rotation 1 0 0 1.5708
  children [
    DEF WALL_H Shape {
      appearance USE WALL_APPEARANCE
      geometry Box {
        size 0.022 0.07 2.044
      }
    }
  ]
  name "wall_left"
  boundingObject USE WALL_H
}
Solid {
  translation 1.511 0 0.035
  rotation 1 0 0 1.5708
  children [
    USE WALL_H
  ]
  name "wall_right"
  boundingObject USE WALL_H
}
Robot {
  children [
    DEF ROBOT_BODY_BOUND Transform {
      translation 0 0 0.175
      children [
        DEF ROBOT_BODY Shape {
          appearance CorrodedMetal {
            IBLStrength 20
          }
          geometry Box {
            size 0.2 0.36 0.34
          }
        }
      ]
    }
    HingeJoint {
      jointParameters HingeJointParameters {
        axis 0 1 0
        anchor 0 -0.19 0.05
      }
      device [
        RotationalMotor {
          name "motor_r"
        }
      ]
      endPoint Solid {
        translation 0 -0.19 0.05
        children [
          DEF ROBOT_WHEEL Shape {
            appearance Rubber {
            }
            geometry Cylinder {
              height 0.02
              radius 0.05
            }
          }
        ]
        name "wheel_r"
        boundingObject USE ROBOT_WHEEL
        physics Physics {
        }
      }
    }
    HingeJoint {
      jointParameters HingeJointParameters {
        axis 0 1 0
        anchor 0 0.19 0.05
      }
      device [
        RotationalMotor {
          name "motor_l"
        }
      ]
      endPoint Solid {
        translation 0 0.19 0.05
        rotation 0 -1 0 0.08462082290631825
        children [
          USE ROBOT_WHEEL
        ]
        name "wheel_l"
        boundingObject USE ROBOT_WHEEL
        physics Physics {
        }
      }
    }
  ]
  boundingObject USE ROBOT_BODY_BOUND
  physics Physics {
    density -1
    mass 10
  }
}
