#VRML_SIM R2023b utf8

EXTERNPROTO "../protos/OpponentBox.proto"
EXTERNPROTO "../protos/Judge.proto"
EXTERNPROTO "../protos/StaticObjects.proto"
EXTERNPROTO "../protos/JetBotRaspberryPiCamera.proto"
EXTERNPROTO "../protos/GenericRobot.proto"
EXTERNPROTO "https://raw.githubusercontent.com/cyberbotics/webots/R2023b/projects/objects/backgrounds/protos/TexturedBackground.proto"
EXTERNPROTO "https://raw.githubusercontent.com/cyberbotics/webots/R2023b/projects/objects/backgrounds/protos/TexturedBackgroundLight.proto"

WorldInfo {
  basicTimeStep 10
  contactProperties [
    ContactProperties {
      material1 "floor"
      material2 "wheel"
      coulombFriction [
        100
      ]
    }
    ContactProperties {
      coulombFriction [
        0.1
      ]
    }
  ]
}
Viewpoint {
  orientation 0.3012494292415356 -0.004089156126535691 -0.9535366066301921 3.154844695132597
  position 4.833557913120399 -0.1884364449862949 3.4187216736615205
}
TexturedBackground {
}
TexturedBackgroundLight {
}
StaticObjects {
}
DEF ROBOT_OPPONENT_BIG OpponentBox {
  name "opponent_box_big"
  translation 0.035 1.195 0
  rotation 0 0 1 0
}
DEF ROBOT_OPPONENT_SMALL OpponentBox {
  name "opponent_box_small"
  translation 0.72 1.16 0
  rotation 0 0 1 -1.571595307179586
  arucoNumber 2
}
DEF JUDGE Judge {
}
Robot {
  translation -0.1 1.50976 1.05
  rotation 0.4472158700299192 0.4472128700307911 -0.7745957748866213 1.82349
  children [
    JetBotRaspberryPiCamera {
      rotation 0 1 0 0
      name "RasPi0"
      fieldOfView 2.15
      width 1920
      height 1080
    }
  ]
  name "camera_central"
  controller "<extern>"
}
DEF ROBOT_SMALL GenericRobot {
  name "robot_small"
  translation 0.12 -1.25 0
  rotation 0 0 1 1.5708
  arucoNumber 6
}
DEF ROBOT_BIG GenericRobot {
  name "robot_big"
  translation 0.815 -1.33 0
  rotation 0 0 1 -1.5708
  arucoNumber 7
  baseSlot [
    Solid {
      translation 0.1 0 0.08
      children [
        HingeJoint {
          jointParameters HingeJointParameters {
            axis 0 0 1
          }
          device [
            RotationalMotor {
              name "m6"
              controlPID 1000 0 0
              maxTorque 1000
            }
            PositionSensor {
            }
          ]
          endPoint Solid {
            translation 0 0.06 0
            children [
              Shape {
                appearance PBRAppearance {
                  baseColor 0.666667 0 0
                  metalness 0.2
                }
                geometry Box {
                  size 0.02 0.1 0.02
                }
              }
            ]
          }
        }
      ]
    }
  ]
}
DEF Columns_Platform Solid {
  translation 0.0499997 -0.4 0.06
  rotation 0 0 1 1.5708
  children [
    DEF g0 Group {
      children [
        DEF platform Pose {
          translation 0 0 0.063
          children [
            Shape {
              appearance PBRAppearance {
                baseColor 1 0.639216 0.282353
                roughness 1
                metalness 0
              }
              geometry Box {
                size 0.4 0.1 0.015
              }
              castShadows FALSE
            }
          ]
        }
        DEF cilindar_4 Pose {
          translation 0.15 0 0
          children [
            Shape {
              appearance PBRAppearance {
                baseColor 0.207843 0.517647 0.894118
                roughness 1
                metalness 0
              }
              geometry Cylinder {
                height 0.109
                radius 0.0365
              }
              castShadows FALSE
            }
          ]
        }
        DEF cilindar_3 Pose {
          translation 0.05 0 0
          children [
            Shape {
              appearance PBRAppearance {
                baseColor 0.109804 0.443137 0.847059
                roughness 1
                metalness 0
              }
              geometry Cylinder {
                height 0.109
                radius 0.0365
              }
              castShadows FALSE
            }
          ]
        }
        DEF cilindar_2 Pose {
          translation -0.05 0 0
          children [
            Shape {
              appearance PBRAppearance {
                baseColor 0.101961 0.372549 0.705882
                roughness 1
                metalness 0
              }
              geometry Cylinder {
                height 0.109
                radius 0.0365
              }
              castShadows FALSE
            }
          ]
        }
        DEF cilindar_1 Pose {
          translation -0.15 0 0
          children [
            Shape {
              appearance PBRAppearance {
                baseColor 0.101961 0.372549 0.705882
                roughness 1
                metalness 0
              }
              geometry Cylinder {
                height 0.109
                radius 0.0365
              }
              castShadows FALSE
            }
          ]
        }
      ]
    }
  ]
  name "Columns_Platform"
  boundingObject USE g0
  physics Physics {
  }
}
DEF Side_of_table Solid {
  translation -0.8 0 0.0275
  children [
    DEF G1 Group {
      children [
        DEF Scene Pose {
          children [
            Shape {
              appearance PBRAppearance {
                baseColor 0.141176 0.121569 0.192157
                roughness 1
                metalness 0
              }
              geometry Box {
                size 0.4 0.9 0.055
              }
              castShadows FALSE
            }
          ]
        }
      ]
    }
  ]
  name "Side_of_table"
  boundingObject USE G1
  physics Physics {
  }
}
