#VRML_SIM R2021b utf8
WorldInfo {
  CFM 1e-08
  basicTimeStep 16
}
Viewpoint {
  orientation 0.29360587467357135 -0.5052415400705318 -0.8114965043327816 2.260289589493047
  position -2.7677312389525763 0.6098302303540731 1.4323220809510093
}
TexturedBackground {
}
TexturedBackgroundLight {
}
Floor {
  rotation 1 0 0 1.5707996938995747
  name "table"
  size 3 2
  tileSize 4.096 2.048
  appearance PBRAppearance {
    baseColorMap ImageTexture {
      url [
        "assets/table.png"
      ]
      repeatS FALSE
      repeatT FALSE
    }
    roughness 1
    metalness 0
  }
}
Shape {
  appearance PBRAppearance {
    baseColor 1 0 1
    metalness 0
    name "purple statuette support"
  }
  geometry IndexedFaceSet {
    coord Coordinate {
      point [
        1.5 -0.49 0.07
        1.5 -0.49 0.048
        1.5 -0.69082 0.07
        1.5 -0.69082 0.048
        0.99 -1 0.07
        0.99 -1 0.048
        1.19082 -1 0.07
        1.19082 -1 0.048
      ]
    }
    normal Normal {
      vector [
        0 0 1
        0 0 1
        0 0 -1
        0 0 -1
        1 0 0
        1 0 0
        -0.70711 0.70711 0
        -0.70711 0.70711 0
        0 -1 0
        0 -1 0
        0.70711 -0.70711 0
        0.70711 -0.70711 0
      ]
    }
    normalPerVertex FALSE
    coordIndex [
      0, 4, 2, -1, 2, 4, 6, -1, 1, 3, 5, -1, 3, 7, 5, -1, 0, 2, 1, -1, 1, 2, 3, -1, 0, 1, 4, -1, 1, 5, 4, -1, 4, 5, 6, -1, 5, 7, 6, -1, 2, 6, 3, -1, 3, 6, 7, -1
    ]
  }
  isPickable FALSE
}
Shape {
  appearance PBRAppearance {
    baseColor 1 1 0
    metalness 0
    name "yellow statuette support"
  }
  geometry IndexedFaceSet {
    coord Coordinate {
      point [
        -1.5 -0.49 0.07
        -1.5 -0.49 0.048
        -1.5 -0.69082 0.07
        -1.5 -0.69082 0.048
        -0.99 -1 0.07
        -0.99 -1 0.048
        -1.19082 -1 0.07
        -1.19082 -1 0.048
      ]
    }
    normal Normal {
      vector [
        0 0 1
        0 0 1
        0 0 -1
        0 0 -1
        1 0 0
        1 0 0
        -0.70711 0.70711 0
        -0.70711 0.70711 0
        0 -1 0
        0 -1 0
        0.70711 -0.70711 0
        0.70711 -0.70711 0
      ]
    }
    normalPerVertex FALSE
    coordIndex [
      0, 2, 4, -1, 2, 6, 4, -1, 1, 5, 3, -1, 3, 5, 7, -1, 0, 1, 2, -1, 1, 3, 2, -1, 0, 4, 1, -1, 1, 4, 5, -1, 4, 6, 5, -1, 5, 6, 7, -1, 2, 3, 6, -1, 3, 7, 6, -1
    ]
  }
  isPickable FALSE
}
Solid {
  translation 0 1.009 0.035
  rotation 1 0 0 1.5708
  children [
    DEF WALL_W Shape {
      appearance DEF WALL_APPEARANCE PBRAppearance {
        baseColor 1 1 0.498039
        roughness 1
        metalness 0
      }
      geometry Box {
        size 3 0.07 0.018
      }
    }
  ]
  name "wall_top"
  boundingObject USE WALL_W
}
Solid {
  translation 0 -1.009 0.035
  rotation 1 0 0 1.5708
  children [
    USE WALL_W
  ]
  name "wall_bottom"
  boundingObject USE WALL_W
}
Solid {
  translation -1.509 0 0.035
  rotation 1 0 0 1.5708
  children [
    DEF WALL_H Shape {
      appearance USE WALL_APPEARANCE
      geometry Box {
        size 0.018 0.07 2.036
      }
    }
  ]
  name "wall_left"
  boundingObject USE WALL_H
}
Solid {
  translation 1.509 0 0.035
  rotation 1 0 0 1.5708
  children [
    USE WALL_H
  ]
  name "wall_right"
  boundingObject USE WALL_H
}
Robot {
  children [
    DEF ROBOT_BODY_BOUND Transform {
      translation 0 0 0.175
      children [
        DEF ROBOT_BODY Shape {
          appearance CorrodedMetal {
            IBLStrength 20
          }
          geometry Box {
            size 0.2 0.36 0.34
          }
        }
      ]
    }
    HingeJoint {
      jointParameters HingeJointParameters {
        axis 0 1 0
        anchor 0 -0.19 0.05
      }
      device [
        RotationalMotor {
          name "motor_r"
        }
      ]
      endPoint Solid {
        translation 0 -0.19 0.05
        children [
          DEF ROBOT_WHEEL Shape {
            appearance Rubber {
            }
            geometry Cylinder {
              height 0.02
              radius 0.05
            }
          }
        ]
        name "wheel_r"
        boundingObject USE ROBOT_WHEEL
        physics Physics {
        }
      }
    }
    HingeJoint {
      jointParameters HingeJointParameters {
        axis 0 1 0
        anchor 0 0.19 0.05
      }
      device [
        RotationalMotor {
          name "motor_l"
        }
      ]
      endPoint Solid {
        translation 0 0.19 0.05
        rotation 0 -1 0 0.08462082290631825
        children [
          USE ROBOT_WHEEL
        ]
        name "wheel_l"
        boundingObject USE ROBOT_WHEEL
        physics Physics {
        }
      }
    }
  ]
  boundingObject USE ROBOT_BODY_BOUND
  physics Physics {
    density -1
    mass 10
  }
}
